Workbook
Name \a: BS_TH!#REF!
Name \a: PL!#REF!
Name \a: PL_TH!#REF!
Name \a: BS!#REF!
Name \c: BS_TH!#REF!
Name \c: PL!#REF!
Name \c: PL_TH!#REF!
Name \c: BS!#REF!
Name \d: BS_TH!#REF!
Name \d: PL!#REF!
Name \d: PL_TH!#REF!
Name \d: BS!#REF!
Name PL: '[1]BS-6'!#REF!
Name Print_Area_MI: BS_TH!$A$64:$J$76
Name Print_Area_MI: PL!#REF!
Name Print_Area_MI: PL_TH!#REF!
Name Print_Area_MI: BS!$A$50:$Q$82

Sheet แนวข้อสอบFOB67
A1: อาจารย์อาริตออกงบแบบไม่แยกรายได้กับค่าใช้จ่าย >> ต้องจัดประเภทแล้วคำนวน Total revenue กับ Total expense ใหม่
A2: ดอกเบี้ยจ่าย Interest = ต้นทุนทางการเงิน
A3: มูลค่าหุ้นไม่ได้ใช้ 1 บาท

Sheet Ratio
A1: Par Value Per Share
A25: Earning Per Share
A38: Formular | C38: 2022
A39: Net income | C39: =PL!J71 -> -213062095 | D39: = | E39: =C39/C40 -> -0.047017386
A40: Common Stock | C40: =BS!J82 -> 4531559733
C42: 2023
C43: =PL!H33 -> 759876806 | D43: = | E43: =C43/C44 -> 0.16768549
C44: =BS!H82 -> 4531559733
A56: Dividend Per Share
C68: =0.07*C44 -> 3.1720918e+08
A71: Book Value Per Share
A88: 1. Liqudity
A89: 1.1 Current Ratio
A90: Current Asset | C90: = | D90: =BS!H15 -> 1885481783
A91: Current Liabiliy | D91: =BS!H49 -> 3057931555
C93: = | D93: =D90/D91 -> 0.61658731 | E93: เท่า
C95: = | D95: =1/D93 -> 1.6218303 | E95: %
A98: 1.2 Quick Ratio (ไม่รวมตั้งแต่ Inventory ลงมา)
A99: CA - Invetory - Prepaid Expense | D99: = | E99: =SUM(BS!H10:H11) -> 1386530926
A100: CL | E100: =BS!H49 -> 3057931555
D102: = | E102: =E99/E100 -> 0.45342118 | F102: เท่า
A105: 2. Asset Management Ratio
A106: 2.1 Inventory Turnover Ratio
A107: 1. | B107: Sales | D107: =SUM(PL!H10:H11) -> 6986483866 | E107: = | F107: =D107/D108 -> 151.17419 | G107: รอบ(ครั้ง) | I107: =365/151 -> 2.4172185 | J107: วัน | K107: เพราะว่าธุรกิจโรงแรมรายได้หลักไม่ได้อยู่ที่ Inventory
B108: Avg.Inventory | D108: =(BS!J12+BS!H12)/2 -> 46214792 | E108: (ต้นงวด+ปลายงวด)/2
A110: 2. | B110: Sales
B111: Inventory
A113: 3. | B113: Cost of goods sold | D113: =SUM(PL!H18:H19) -> 3034517722 | F113: =D113/D114 -> 65.661179 | G113: รอบ(ครั้ง) | I113: =365/F113 -> 5.5588402 | J113: วัน
B114: Avg.Inventory | D114: 46214792 | E114: (ต้นงวด+ปลายงวด)/2
A116: 4. | B116: Cost of goods sold
B117: Inventory
A120: 2.2 Account Receivable Turnover
A121: 1. | B121: Sales | D121: =SUM(PL!H10:H11) -> 6986483866 | F121: =D121/D122 -> 42.389566 | G121: ครั้ง | I121: =365/42 -> 8.6904762 | J121: วัน
B122: Avg.AR | D122: =(BS!H11+BS!J11)/2 -> 1.6481612e+08 | E122: (ต้นงวด+ปลายงวด)/2
A124: 2. | B124: Sales | D124: 6986483866 | F124: =D124/D125 -> 41.138853 | G124: ครั้ง | I124: =365/41 -> 8.902439 | J124: วัน
B125: AR | D125: =BS!H11 -> 169826900
A128: 2.3 Fixed Asset Turnover
A129: Sales | D129: =PL!H15 -> 7046289675 | F129: =D129/D130 -> 0.32338081 | G129: เท่า
A130: Net Fixed Assets | D130: =BS!H27 -> 21789448871
A133: 2.4 Total asset turnover
...

Sheet 1. Liqudity

Sheet 2. Asset Management Ratioeet4

Sheet 3. Debt management ratio

Sheet 4. Profitability Ratio

Sheet 5. Market Value Ratio

Sheet BS
A1: The Erawan Group Public Company Limited and its Subsidiaries
A2: Statement of financial position
I4: Consolidated | M4: Separate
H5: financial statements | L5: financial statements
H6: 31 December | L6: 31 December
A7: Assets | E7: สินทรัพย์ | F7: Note | H7: 2023 | J7: 2022 | L7: 2023 | N7: 2022
H8: (in Baht)
A9: Current assets | E9: สินทรัพย์หมุนเวียน
A10: Cash and cash equivalents | E10: เงินสดและรายการเทียบเท่าเงินสด | F10: 5 | H10: 1216704026 | J10: 1531836414 | L10: 344760001 | N10: 673867707
A11: Trade accounts receivable | E11: ลูกหนี้การค้า | F11: 4, 6 | H11: 169826900 | J11: 159805341 | L11: 78896760 | N11: 71653526
A12: Inventories | E12: สินค้าคงเหลือ | F12: 7 | H12: 48962953 | J12: 43466631 | L12: 7616886 | N12: 8714723
A13: Value added tax refundable | E13: ภาษีมูลค่าเพิ่มรอเรียกคืน | H13: 228580712 | J13: 177576357 | L13: 0 | N13: 0
A14: Other current assets | E14: สินทรัพย์หมุนเวียนอื่น | F14: 4, 8 | H14: 221407192 | J14: 113631403 | L14: 130412019 | N14: 38670904
A15: Total current assets | E15: รวมสินทรัพย์หมุนเวียน | H15: =SUM(H10:H14) -> 1885481783 | J15: =SUM(J10:J14) -> 2026316146 | L15: =SUM(L10:L14) -> 561685666 | N15: =SUM(N10:N14) -> 792906860
A17: Non-current assets | E17: สินทรัพย์ไม่หมุนเวียน
A18: Investments in associates | E18: เงินลงทุนในบริษัทร่วม | F18: 9 | H18: 83488877 | J18: 62632269 | L18: 228075217 | N18: 240543097
A19: Investments in subsidiaries | E19: เงินลงทุนในบริษัทย่อย | F19: 10 | H19: 0 | J19: 0 | L19: 5612102226 | N19: 5612632216
A20: Other non-current financial assets | E20: สินทรัพย์ทางการเงินไม่หมุนเวียนอื่น | F20: 11 | H20: 257537 | J20: 505335 | L20: 244620 | N20: 430066
A21: Long-term loans to related parties | E21: เงินให้กู้ยืมระยะยาวแก่กิจการที่เกี่ยวข้องกัน | F21: 4 | H21: 0 | J21: 0 | L21: 1316943030 | N21: 412033113
A22: Property, plant and equipment | E22: ที่ดิน อาคารและอุปกรณ์ | F22: 13 | H22: 21395547359 | J22: 19284913065 | L22: 8920582980 | N22: 9190577211
A23: Intangible assets | E23: สินทรัพย์ไม่มีตัวตน | F23: 14 | H23: 27343823 | J23: 34867102 | L23: 11304242 | N23: 16274795
A24: Deposits for lease of land, building and equipment | E24: เงินมัดจำการเช่าที่ดิน อาคารและอุปกรณ์ | F24: 4 | H24: 164614090 | J24: 163885908 | L24: 78994283 | N24: 97157128
A25: Deferred tax assets | E25: สินทรัพย์ภาษีเงินได้รอการตัดบัญชี | F25: 27 | H25: 50998463 | J25: 41069286 | L25: 0 | N25: 0
A26: Other non-current assets | E26: สินทรัพย์ไม่หมุนเวียนอื่น | F26: 15 | H26: 67198722 | J26: 97622529 | L26: 20588846 | N26: 17623099
A27: Total non-current assets | E27: รวมสินทรัพย์ไม่หมุนเวียน | H27: =SUM(H18:H26) -> 21789448871 | J27: =SUM(J18:J26) -> 19685495494 | K27: =SUM(K19:K26) -> 0 | L27: =SUM(L18:M26) -> 16188835444 | N27: =SUM(N18:O26) -> 15587270725
A29: Total assets | E29: รวมสินทรัพย์ | H29: =H15+H27 -> 23674930654 | J29: =J15+J27 -> 21711811640 | L29: =L15+L27 -> 16750521110 | N29: =N15+N27 -> 16380177585
A33: The Erawan Group Public Company Limited and its Subsidiaries
A34: Statement of financial position
I36: Consolidated | M36: Separate
H37: financial statements | L37: financial statements
H38: 31 December | L38: 31 December
A39: Liabilities and equity | E39: หนี้สินและส่วนของผู้ถือหุ้น | F39: Note | H39: 2023 | J39: 2022 | L39: 2023 | N39: 2022
H40: (in Baht)
A41: Current liabilities | E41: หนี้สินหมุนเวียน
A42: Short-term borrowings from financial institutions | E42: เงินกู้ยืมระยะสั้นจากสถาบันการเงิน | F42: 16 | H42: 820000000 | J42: 300000000 | L42: 570000000 | N42: 0
A43: Trade accounts payable | E43: เจ้าหนี้การค้า | F43: 4, 17 | H43: 226852982 | J43: 234512909 | L43: 99239649 | N43: 96195987
A44: Current portion of long-term borrowings | E44: เงินกู้ยืมระยะยาวจากสถาบันการเงิน
B45: from financial institutions | E45: ส่วนที่ถึงกำหนดชำระภายในหนึ่งปี | F45: 16 | H45: 931872838 | J45: 482530445 | L45: 420815603 | N45: 245435603
A46: Current portion of lease liabilities | E46: ส่วนของหนี้สินตามสัญญาเช่าที่ถึงกำหนดชำระภายในหนึ่งปี | F46: 16 | H46: 244111914 | J46: 70011916 | L46: 169599889 | N46: 379688
A47: Corporate income tax payable | E47: ภาษีเงินได้นิติบุคคลค้างจ่าย | H47: 10125354 | J47: 71341 | L47: 0 | N47: 0
...

Sheet PL
A1: The Erawan Group Public Company Limited and its Subsidiaries
A2: Statement of comprehensive income
I4: Consolidated | M4: Separate
H5: financial statements | L5: financial statements
H6: Year ended 31 December | L6: Year ended 31 December
F7: Note | H7: 2023 | J7: 2022 | L7: 2023 | N7: 2022
H8: (in Baht)
A9: Revenues | E9: รายได้
A10: Revenues from hotel operations | E10: รายได้จากการประกอบกิจการโรงแรม | F10: 4 | H10: 6902059525 | J10: 4563597529 | L10: 3288322052 | N10: 2107924488
A11: Rental of units in buildings and service income | E11: รายได้จากค่าเช่าห้องในอาคารและค่าบริการ | F11: 4 | H11: 84424341 | J11: 64985480 | L11: 19081183 | N11: 13370309
A12: Dividend income | E12: เงินปันผลรับ | F12: 9, 10 | H12: 0 | J12: 0 | L12: 3152190 | N12: 16694685
A13: Interest income | E13: รายได้ดอกเบี้ย | F13: 4 | H13: 6825646 | J13: 2681086 | L13: 46242003 | N13: 28808371
A14: Other income | E14: รายได้อื่น | F14: 4, 13, 23 | H14: 52980163 | J14: 86023455 | L14: 57205407 | N14: 67268388
A15: Total revenues | E15: รวมรายได้ | H15: =SUM(H10:H14) -> 7046289675 | J15: =SUM(J10:J14) -> 4717287550 | L15: =SUM(L10:L14) -> 3414002835 | N15: =SUM(N10:N14) -> 2234066241
A17: Expenses | E17: ค่าใช้จ่าย
A18: Cost of hotel operations | E18: ต้นทุนจากการประกอบกิจการโรงแรม | F18: 4 | H18: 2973801686 | J18: 2243034557 | L18: 1312958734 | N18: 1000554260
A19: Cost of rental of units in buildings and services | E19: ต้นทุนจากการให้เช่าห้องในอาคารและค่าบริการ | F19: 4 | H19: 60716036 | J19: 39117354 | L19: 0 | N19: 0
A20: Depreciation and amortisation | E20: ค่าเสื่อมราคาและค่าตัดจำหน่าย | H20: 901089744 | J20: 871843735 | L20: 413354520 | N20: 439247135
A21: Selling expenses | E21: ค่าใช้จ่ายในการขาย | H21: 369125721 | J21: 267439623 | L21: 184713757 | N21: 131615473
A22: Administrative expenses | E22: ค่าใช้จ่ายในการบริหาร | F22: 4 | H22: 1469174766 | J22: 1110039549 | L22: 708896142 | N22: 577075060
A23: Loss on impairment of non-financial assets | E23: ขาดทุนจากการด้อยค่าสินทรัพย์ที่ไม่ใช่สินทรัพย์ทางการเงิน | F23: 13 | H23: 0 | J23: 7600000 | L23: 0 | N23: 0
A24: Total expenses | E24: รวมค่าใช้จ่าย | H24: =SUM(H18:H23) -> 5773907953 | J24: =SUM(J18:J23) -> 4539074818 | L24: =SUM(L18:L23) -> 2619923153 | N24: =SUM(N18:N23) -> 2148491928
A26: Profit from operating activities | E26: กำไรจากกิจกรรมดำเนินงาน | H26: =H15-H24 -> 1272381722 | J26: =J15-J24 -> 178212732 | L26: =L15-L24 -> 794079682 | N26: =N15-N24 -> 85574313
A27: Reversal (loss) on impairment of financial assets | E27: กลับรายการ (ขาดทุน) จากการด้อยค่าสินทรัพย์ทางการเงิน | F27: 4, 6 | H27: 23481390 | J27: 12427690 | L27: 908141 | N27: -95718275
A28: Finance costs | E28: ต้นทุนทางการเงิน | F28: 4, 26 | H28: -588988360 | J28: -457854856 | L28: -324168568 | N28: -261451193
A29: Share of profit of associates
B30: accounted for using equity method | E30: ส่วนแบ่งกำไรจากเงินลงทุนในบริษัทร่วมที่ใช้วิธีส่วนได้เสีย | F30: 9 | H30: 36476679 | J30: 28599509 | L30: 0 | N30: 0
A31: Profit (loss) before income tax expense | E31: กำไร (ขาดทุน) ก่อนภาษีเงินได้ | H31: =SUM(H26:H30) -> 743351431 | J31: =SUM(J26:J30) -> -238614925 | L31: =SUM(L26:L30) -> 470819255 | N31: =SUM(N26:N30) -> -271595155
A32: Tax income | E32: รายได้ภาษีเงินได้ | F32: 27 | H32: 16525375 | J32: 25552830 | L32: 7760163 | N32: 5908377
A33: Profit (loss) for the year | E33: กำไร (ขาดทุน) สำหรับปี | H33: =SUM(H31:H32) -> 759876806 | J33: =SUM(J31:J32) -> -213062095 | L33: =SUM(L31:L32) -> 478579418 | N33: =SUM(N31:N32) -> -265686778
A36: The Erawan Group Public Company Limited and its Subsidiaries
A37: Statement of comprehensive income
I39: Consolidated | M39: Separate
H40: financial statements | L40: financial statements
H41: Year ended 31 December | L41: Year ended 31 December
F42: Note | H42: 2023 | J42: 2022 | L42: 2023 | N42: 2022
H43: (in Baht)
A44: Other comprehensive income
A45: Items that will be reclassified
B46: subsequently to profit or loss
...

Sheet BS_TH
A1: บริษัท ดิ เอราวัณ กรุ๊ป จำกัด (มหาชน) และบริษัทย่อย
A2: งบแสดงฐานะการเงิน
D4: งบการเงินรวม | H4: งบการเงินเฉพาะกิจการ
D5: 31 ธันวาคม | H5: 31 ธันวาคม
A6: สินทรัพย์ | B6: หมายเหตุ | D6: 2566 | F6: 2565 | H6: 2566 | J6: 2565
D7: (บาท)
A8: สินทรัพย์หมุนเวียน
A9: เงินสดและรายการเทียบเท่าเงินสด | B9: 5 | D9: 1216704026 | F9: 1531836414 | H9: 344760001 | J9: 673867707
A10: ลูกหนี้การค้า | B10: 4, 6 | D10: 169826900 | F10: 159805341 | H10: 78896760 | J10: 71653526
A11: สินค้าคงเหลือ | B11: 7 | D11: 48962953 | F11: 43466631 | H11: 7616886 | J11: 8714723
A12: ภาษีมูลค่าเพิ่มรอเรียกคืน | D12: 228580712 | F12: 177576357 | H12: 0 | J12: 0
A13: สินทรัพย์ไม่หมุนเวียนที่จัดประเภท
A14: เป็นสินทรัพย์ที่ถือไว้เพื่อขาย | B14: 14 | F14: 0 | J14: 0
A15: สินทรัพย์หมุนเวียนอื่น | B15: 4, 8 | D15: 221407192 | F15: 113631403 | H15: 130412019 | J15: 38670904
A16: รวมสินทรัพย์หมุนเวียน | D16: =SUM(D9:D15) -> 1885481783 | F16: =SUM(F9:F15) -> 2026316146 | H16: =SUM(H9:H15) -> 561685666 | J16: =SUM(J9:J15) -> 792906860
A18: สินทรัพย์ไม่หมุนเวียน
A19: เงินลงทุนในบริษัทร่วม | B19: 9 | D19: 83488877 | F19: 62632269 | H19: 228075217 | J19: 240543097
A20: เงินลงทุนในบริษัทย่อย | B20: 10 | D20: 0 | F20: 0 | H20: 5612102226 | J20: 5612632216
A21: สินทรัพย์ทางการเงินไม่หมุนเวียนอื่น | B21: 11 | D21: 257537 | F21: 505335 | H21: 244620 | J21: 430066
A22: เงินให้กู้ยืมระยะยาวแก่กิจการที่เกี่ยวข้องกัน | B22: 4 | D22: 0 | F22: 0 | H22: 1316943030 | J22: 412033113
A23: ที่ดิน อาคารและอุปกรณ์ | B23: 13 | D23: 21395547359 | F23: 19284913065 | H23: 8920582980 | J23: 9190577211
A24: สินทรัพย์ไม่มีตัวตน | B24: 14 | D24: 27343823 | F24: 34867102 | H24: 11304242 | J24: 16274795
A25: เงินมัดจำการเช่าที่ดิน อาคารและอุปกรณ์ | B25: 4 | D25: 164614090 | F25: 163885908 | H25: 78994283 | J25: 97157128
A26: สินทรัพย์ภาษีเงินได้รอการตัดบัญชี | B26: 27 | D26: 50998463 | F26: 41069286 | H26: 0 | J26: 0
A27: สินทรัพย์ไม่หมุนเวียนอื่น | B27: 15 | D27: 67198722 | F27: 97622529 | H27: 20588846 | J27: 17623099
A28: รวมสินทรัพย์ไม่หมุนเวียน | D28: =SUM(D19:D27) -> 21789448871 | E28: 0 | F28: =SUM(F19:F27) -> 19685495494 | G28: 0 | H28: =SUM(H19:H27) -> 16188835444 | J28: =SUM(J19:J27) -> 15587270725
A30: รวมสินทรัพย์ | D30: =SUM(D16+D28) -> 23674930654 | F30: =SUM(F16+F28) -> 21711811640 | H30: =SUM(H16+H28) -> 16750521110 | J30: =SUM(J16+J28) -> 16380177585
A33: บริษัท ดิ เอราวัณ กรุ๊ป จำกัด (มหาชน) และบริษัทย่อย
A34: งบแสดงฐานะการเงิน
D36: งบการเงินรวม | H36: งบการเงินเฉพาะกิจการ
D37: 31 ธันวาคม | H37: 31 ธันวาคม
A38: หนี้สินและส่วนของผู้ถือหุ้น | B38: หมายเหตุ | D38: 2566 | F38: 2565 | H38: 2566 | J38: 2565
D39: (บาท)
A40: หนี้สินหมุนเวียน
A41: เงินกู้ยืมระยะสั้นจากสถาบันการเงิน | B41: 16 | D41: 820000000 | F41: 300000000 | H41: 570000000 | J41: 0
A42: เจ้าหนี้การค้า | B42: 4, 17 | D42: 226852982 | F42: 234512909 | H42: 99239649 | J42: 96195987
A43: เงินกู้ยืมระยะยาวจากสถาบันการเงิน
A44: ส่วนที่ถึงกำหนดชำระภายในหนึ่งปี | B44: 16 | D44: 931872838 | F44: 482530445 | H44: 420815603 | J44: 245435603
A45: ส่วนของหนี้สินตามสัญญาเช่า
A46: ที่ถึงกำหนดชำระภายในหนึ่งปี | B46: 16 | D46: 244111914 | F46: 70011916 | H46: 169599889 | J46: 379688
...

Sheet PL_TH
A1: บริษัท ดิ เอราวัณ กรุ๊ป จำกัด (มหาชน) และบริษัทย่อย
A2: งบกำไรขาดทุนเบ็ดเสร็จ
E4: งบการเงินรวม | H4: งบการเงินเฉพาะกิจการ
D5: สำหรับปีสิ้นสุดวันที่ | H5: สำหรับปีสิ้นสุดวันที่
D6: 31 ธันวาคม | H6: 31 ธันวาคม
B7: หมายเหตุ | D7: 2566 | F7: 2565 | H7: 2566 | J7: 2565
D8: (บาท)
A9: รายได้
A10: รายได้จากการประกอบกิจการโรงแรม | B10: 4 | D10: 6902059525 | F10: 4563597529 | H10: 3288322052 | J10: 2107924488
A11: รายได้จากค่าเช่าห้องในอาคารและค่าบริการ | B11: 4 | D11: 84424341 | F11: 64985480 | H11: 19081183 | J11: 13370309
A12: เงินปันผลรับ | B12: 9, 10 | D12: 0 | F12: 0 | H12: 3152190 | J12: 16694685
A13: รายได้ดอกเบี้ย | B13: 4 | D13: 6825646 | F13: 2681086 | H13: 46242003 | J13: 28808371
A14: รายได้อื่น | B14: 4, 13, 23 | D14: 52980163 | F14: 86023455 | H14: 57205407 | J14: 67268388
A15: รวมรายได้ | D15: =SUM(D10:D14) -> 7046289675 | F15: =SUM(F10:F14) -> 4717287550 | H15: =SUM(H10:H14) -> 3414002835 | J15: =SUM(J10:J14) -> 2234066241
A17: ค่าใช้จ่าย
A18: ต้นทุนจากการประกอบกิจการโรงแรม | B18: 4 | D18: 2973801686 | F18: 2243034557 | H18: 1312958734 | J18: 1000554260
A19: ต้นทุนจากการให้เช่าห้องในอาคารและค่าบริการ | B19: 4 | D19: 60716036 | F19: 39117354 | H19: 0 | J19: 0
A20: ค่าเสื่อมราคาและค่าตัดจำหน่าย | D20: 901089744 | F20: 871843735 | H20: 413354520 | J20: 439247135
A21: ค่าใช้จ่ายในการขาย | D21: 369125721 | F21: 267439623 | H21: 184713757 | J21: 131615473
A22: ค่าใช้จ่ายในการบริหาร | B22: 4 | D22: 1469174766 | F22: 1110039549 | H22: 708896142 | J22: 577075060
A23: ขาดทุนจากการด้อยค่าสินทรัพย์ที่ไม่ใช่สินทรัพย์ทางการเงิน | B23: 13 | D23: 0 | F23: 7600000 | H23: 0 | J23: 0
A24: รวมค่าใช้จ่าย | D24: =SUM(D18:D23) -> 5773907953 | F24: =SUM(F18:F23) -> 4539074818 | H24: =SUM(H18:H23) -> 2619923153 | J24: =SUM(J18:J23) -> 2148491928
A26: กำไรจากกิจกรรมดำเนินงาน | D26: =D15-D24 -> 1272381722 | F26: =F15-F24 -> 178212732 | H26: =H15-H24 -> 794079682 | J26: =J15-J24 -> 85574313
A27: กลับรายการ (ขาดทุน) จากการด้อยค่าสินทรัพย์ทางการเงิน | B27: 4, 6 | D27: 23481390 | F27: 12427690 | H27: =21281416-20373275 -> 908141 | J27: -95718275
A28: ต้นทุนทางการเงิน | B28: 4, 26 | D28: -588988360 | F28: -457854856 | H28: -324168568 | J28: -261451193
A29: ส่วนแบ่งกำไรจากเงินลงทุนในบริษัทร่วมที่ใช้วิธีส่วนได้เสีย | B29: 9 | D29: 36476679 | F29: 28599509 | H29: 0 | J29: 0
A30: กำไร (ขาดทุน) ก่อนภาษีเงินได้ | D30: =SUM(D26:D29) -> 743351431 | F30: =SUM(F26:F29) -> -238614925 | H30: =SUM(H26:H29) -> 470819255 | J30: =SUM(J26:J29) -> -271595155
A31: รายได้ภาษีเงินได้ | B31: 27 | D31: 16525375 | F31: 25552830 | H31: 7760163 | J31: 5908377
A32: กำไร (ขาดทุน) สำหรับปี | D32: =SUM(D30:D31) -> 759876806 | F32: =SUM(F30:F31) -> -213062095 | H32: =SUM(H30:H31) -> 478579418 | J32: =SUM(J30:J31) -> -265686778
A34: บริษัท ดิ เอราวัณ กรุ๊ป จำกัด (มหาชน) และบริษัทย่อย
A35: งบกำไรขาดทุนเบ็ดเสร็จ
E37: งบการเงินรวม | H37: งบการเงินเฉพาะกิจการ
D38: สำหรับปีสิ้นสุดวันที่ | H38: สำหรับปีสิ้นสุดวันที่
D39: 31 ธันวาคม | H39: 31 ธันวาคม
B40: หมายเหตุ | D40: 2566 | F40: 2565 | H40: 2566 | J40: 2565
D41: (บาท)
A42: กำไรขาดทุนเบ็ดเสร็จอื่น
A43: รายการที่อาจถูกจัดประเภทใหม่
A44: ไว้ในกำไรหรือขาดทุนในภายหลัง
A45: ผลต่างของอัตราแลกเปลี่ยนจากการแปลงค่างบการเงิน | D45: -111068157 | F45: -135793275 | H45: 0 | J45: 0
...

Sheet SH-10
A1: The Erawan Group Public Company Limited and its Subsidiaries
A2: Statement of changes in equity
D4: Consolidated financial statements
L5: Other components of equity
H6: Retained earnings (deficit)
D7: Issued and | F7: Share premium | R7: Total other | T7: Equity attributable
D8: paid-up | F8: on ordinary | L8: Translation | N8: Fair value | P8: Land revaluation | R8: components | T8: to owners of | V8: Non-controlling | X8: Total
D9: share capital | F9: shares | H9: Legal reserve | J9: Deficit | L9: reserve | N9: reserve | P9: reserve | R9: of equity | T9: the parent | V9: interests | X9: equity
D10: (in Baht)
A11: Year ended 31 December 2022
A12: Balance at 1 January 2022 | D12: 4531559733 | F12: 909993447 | H12: 271330000 | J12: -1758931131 | L12: -83914149 | N12: 108127 | P12: 2141914070 | R12: 2058108048 | T12: 6012060097 | V12: 10659013 | X12: 6022719110
A14: Transactions with owners, recorded directly in equity
A15: Contributions by and distributions to owners of the parent
A16: Issue of ordinary shares | B16: 22 | X16: =SUM(T16:V16) -> 0
A17: Total contribution by and distributions to owners of the parent | D17: =SUM(D16) -> 0 | F17: 0 | H17: 0 | J17: 0 | L17: 0 | N17: 0 | P17: 0 | R17: 0 | T17: =SUM(T16:T16) -> 0 | V17: 0 | X17: =SUM(X16:X16) -> 0
A18: Changes in ownership interests in subsidiaries
A19: Sale of interest in a subsidiary with a change in control | X19: =SUM(T19:V19) -> 0
A20: Total changes in ownership interests in subsidiaries | D20: =SUM(D19) -> 0 | F20: =SUM(F19) -> 0 | H20: =SUM(H19) -> 0 | J20: =SUM(J19) -> 0 | L20: =SUM(L19) -> 0 | N20: =SUM(N19) -> 0 | P20: =SUM(P19) -> 0 | R20: =SUM(R19) -> 0 | T20: =SUM(T19) -> 0 | V20: =SUM(V19) -> 0 | X20: =SUM(X19:X19) -> 0
A22: Total transactions with owners, recorded directly in equity | D22: =D17+D20 -> 0 | F22: =F17+F20 -> 0 | H22: =H17+H20 -> 0 | J22: =J17+J20 -> 0 | L22: =L17+L20 -> 0 | N22: =N17+N20 -> 0 | P22: =P17+P20 -> 0 | R22: =R17+R20 -> 0 | T22: =T17+T20 -> 0 | V22: =V17+V20 -> 0 | X22: =X17+X20 -> 0
A24: Comprehensive income (expense) for the year
A25: Profit (loss) | D25: 0 | F25: 0 | H25: 0 | J25: -224190083 | L25: 0 | N25: 0 | P25: 0 | R25: =SUM(L25:Q25) -> 0 | T25: =SUM(D25:J25,R25) -> -224190083 | V25: 11127988 | X25: =SUM(T25:V25) -> -213062095
A26: Other comprehensive income (expense) | D26: 0 | F26: 0 | H26: 0 | J26: 11318342 | L26: -135793275 | N26: 9922 | P26: 0 | R26: =SUM(L26:Q26) -> -135783353 | T26: =SUM(D26:J26,R26) -> -124465011 | V26: 1362503 | X26: =SUM(T26:V26) -> -123102508
A27: Total comprehensive income (expense) for the year | D27: 0 | F27: 0 | H27: 0 | J27: =SUM(J25:J26) -> -212871741 | L27: =SUM(L25:L26) -> -135793275 | N27: =SUM(N25:N26) -> 9922 | P27: =SUM(P25:P26) -> 0 | R27: =SUM(R25:R26) -> -135783353 | T27: =SUM(T25:T26) -> -348655094 | V27: =SUM(V25:V26) -> 12490491 | X27: =SUM(X25:X26) -> -336164603
A29: Transfer to retained earnings (deficit) | D29: 0 | F29: 0 | H29: 0 | J29: 175082808 | L29: 0 | N29: 0 | P29: -140010984 | R29: =SUM(L29:Q29) -> -140010984 | T29: =SUM(D29:J29,R29) -> 35071824 | V29: 0 | X29: =SUM(T29:V29) -> 35071824
A31: Balance at 31 December 2022 | D31: =SUM(D12,D22,D27,D29) -> 4531559733 | F31: =SUM(F12,F22,F27,F29) -> 909993447 | H31: =SUM(H12,H22,H27,H29) -> 271330000 | J31: =SUM(J12,J22,J27,J29) -> -1796720064 | L31: =SUM(L12,L22,L27,L29) -> -219707424 | N31: =SUM(N12,N22,N27,N29) -> 118049 | P31: =SUM(P12,P22,P27,P29) -> 2001903086 | R31: =SUM(R12,R22,R27,R29) -> 1782313711 | T31: =SUM(T12,T22,T27,T29) -> 5698476827 | V31: =SUM(V12,V22,V27,V29) -> 23149504 | X31: =SUM(X12,X22,X27,X29) -> 5721626331
A33: Year ended 31 December 2023
A34: Balance at 1 January 2023 | D34: =D31 -> 4531559733 | F34: =F31 -> 909993447 | H34: =H31 -> 271330000 | J34: =J31 -> -1796720064 | L34: =L31 -> -219707424 | N34: =N31 -> 118049 | P34: =P31 -> 2001903086 | R34: =R31 -> 1782313711 | T34: =T31 -> 5698476827 | V34: =V31 -> 23149504 | X34: =X31 -> 5721626331
A36: Comprehensive income (expense) for the year
A37: Profit | D37: 0 | F37: 0 | H37: 0 | J37: =PL!H69 -> 742656433 | L37: 0 | N37: 0 | P37: 0 | R37: =SUM(L37:P37) -> 0 | T37: =SUM(D37:J37,R37) -> 742656433 | V37: =PL!H70 -> 17220373 | X37: =SUM(T37:V37) -> 759876806
A38: Other comprehensive expense | D38: 0 | F38: 0 | H38: 0 | J38: =+PL!H58+PL!H60 -> -242073 | L38: =PL!H48 -> -111068157 | N38: =+PL!H56 -> -247798 | P38: 0 | R38: =SUM(L38:P38) -> -111315955 | T38: =SUM(D38:J38,R38) -> -111558028 | V38: 0 | X38: =SUM(T38:V38) -> -111558028
A39: Total comprehensive income (expense) for the year | D39: =SUM(D37:D38) -> 0 | F39: =SUM(F37:F38) -> 0 | H39: =SUM(H37:H38) -> 0 | J39: =SUM(J37:J38) -> 742414360 | L39: =SUM(L37:L38) -> -111068157 | N39: =SUM(N37:N38) -> -247798 | P39: =SUM(P37:P38) -> 0 | R39: =SUM(R37:R38) -> -111315955 | T39: =SUM(T37:T38) -> 631098405 | V39: =SUM(V37:V38) -> 17220373 | X39: =SUM(X37:X38) -> 648318778
A41: Transfer to legal reserve | D41: 0 | F41: 0 | H41: 23930000 | J41: =-H41 -> -23930000 | L41: 0 | N41: 0 | P41: 0 | R41: =SUM(L41:P41) -> 0 | T41: =SUM(D41:J41,R41) -> 0 | V41: 0 | X41: =SUM(T41:V41) -> 0
A42: Transfer to retained earnings (deficit) | D42: 0 | F42: 0 | H42: 0 | J42: -46642635 | L42: =-J42 -> 46642635 | N42: 0 | P42: 0 | R42: =SUM(L42:P42) -> 46642635 | T42: =SUM(D42:J42,R42) -> 0 | V42: 0 | X42: =SUM(T42:V42) -> 0
A44: Balance at 31 December 2023 | D44: =SUM(D34,D39,D42,D41) -> 4531559733 | F44: =SUM(F34,F39,F42,F41) -> 909993447 | H44: =SUM(H34,H39,H42,H41) -> 295260000 | J44: =SUM(J34,J39,J42,J41) -> -1124878339 | L44: =SUM(L34,L39,L42,L41) -> -284132946 | N44: =SUM(N34,N39,N42,N41) -> -129749 | P44: =SUM(P34,P39,P42,P41) -> 2001903086 | R44: =SUM(R34,R39,R42,R41) -> 1717640391 | T44: =SUM(T34,T39,T42,T41) -> 6329575232 | V44: =SUM(V34,V39,V42,V41) -> 40369877 | X44: =SUM(X34,X39,X42,X41) -> 6369945109
A84: Retained earnings (deficit)

Sheet SH-11
A1: The Erawan Group Public Company Limited and its Subsidiaries
A2: Statement of changes in equity
D4: Separate financial statements
H5: Retained earnings | L5: Other components of equity
D6: Issued and | F6: Share premium | P6: Total other
D7: paid-up | F7: on ordinary | L7: Fair value | N7: Land revaluation | P7: components | R7: Total
D8: share capital | F8: shares | H8: Legal reserve | J8: Unappropriated | L8: reserve | N8: reserve | P8: of equity | R8: equity
D9: (in Baht)
A10: Year ended 31 December 2022
A11: Balance at 1 January 2022 | D11: 4531559733 | F11: 909993447 | H11: 271330000 | J11: 155122397 | L11: 27716 | N11: 1422526440 | P11: 1422554156 | R11: =SUM(D11:J11)+P11 -> 7290559733
A13: Transactions with owners, recorded directly in equity
A14: Contributions by and distributions to owners of the parent
A15: Issue of ordinary shares | B15: 22 | R15: =SUM(D15:J15)+P15 -> 0
A16: Total contribution by and distributions to owners of the parent | D16: =SUM(D15) -> 0 | F16: =SUM(F15) -> 0 | H16: =SUM(H15) -> 0 | J16: =SUM(J15) -> 0 | L16: =SUM(L15) -> 0 | N16: =SUM(N15) -> 0 | P16: =SUM(P15) -> 0 | R16: =SUM(R15) -> 0
A18: Comprehensive income (expense) for the year
A19: Loss | D19: 0 | F19: 0 | H19: 0 | J19: -265686778 | L19: 0 | N19: 0 | P19: =SUM(L19:N19) -> 0 | R19: =SUM(D19:J19)+P19 -> -265686778
A20: Other comprehensive income | D20: 0 | F20: 0 | H20: 0 | J20: 6772933 | L20: 7426 | N20: 0 | P20: =SUM(L20:N20) -> 7426 | R20: =SUM(D20:J20)+P20 -> 6780359
A21: Total comprehensive income (expense) for the year | D21: =SUM(D19:D20) -> 0 | F21: =SUM(F19:F20) -> 0 | H21: =SUM(H19:H20) -> 0 | J21: =SUM(J19:J20) -> -258913845 | L21: =SUM(L19:L20) -> 7426 | N21: =SUM(N19:N20) -> 0 | P21: =SUM(P19:P20) -> 7426 | R21: =SUM(R19:R20) -> -258906419
A23: Transfer to retained earnings (dificit) | D23: 0 | F23: 0 | H23: 0 | J23: 171227356 | L23: 0 | N23: -136926622 | P23: =SUM(L23:N23) -> -136926622 | R23: =SUM(D23:J23)+P23 -> 34300734
A25: Balance at 31 December 2022 | D25: =SUM(D11,D16,D21,D23) -> 4531559733 | F25: =SUM(F11,F16,F21,F23) -> 909993447 | H25: =SUM(H11,H16,H21,H23) -> 271330000 | J25: =SUM(J11,J16,J21,J23) -> 67435908 | L25: =SUM(L11,L16,L21,L23) -> 35142 | N25: =SUM(N11,N16,N21,N23) -> 1285599818 | P25: =SUM(P11,P16,P21,P23) -> 1285634960 | R25: =SUM(R11,R16,R21,R23) -> 7065954048
A27: Year ended 31 December 2023
A28: Balance at 1 January 2023 | D28: =D25 -> 4531559733 | F28: =F25 -> 909993447 | H28: =H25 -> 271330000 | J28: =J25 -> 67435908 | L28: =L25 -> 35142 | N28: =N25 -> 1285599818 | P28: =P25 -> 1285634960 | R28: =R25 -> 7065954048
A30: Comprehensive income (expense) for the year
A31: Profit | D31: 0 | F31: 0 | H31: 0 | J31: =PL!L69 -> 478579418 | L31: 0 | N31: 0 | P31: =SUM(L31:N31) -> 0 | R31: =SUM(D31:J31,P31) -> 478579418
A32: Other comprehensive expense | D32: 0 | F32: 0 | H32: 0 | J32: 0 | L32: =PL!L56 -> -185446 | N32: 0 | P32: =SUM(L32:N32) -> -185446 | R32: =SUM(D32:J32,P32) -> -185446
A33: Total comprehensiv income (expense) for the year | D33: =SUM(D31:D32) -> 0 | F33: =SUM(F31:F32) -> 0 | H33: =SUM(H31:H32) -> 0 | J33: =SUM(J31:J32) -> 478579418 | L33: =SUM(L31:L32) -> -185446 | N33: =SUM(N31:N32) -> 0 | P33: =SUM(P31:P32) -> -185446 | R33: =SUM(R31:R32) -> 478393972
A35: Transfer to legal reserve | D35: 0 | F35: 0 | H35: 23930000 | J35: =-H35 -> -23930000 | L35: 0 | N35: 0 | P35: =SUM(L35:N35) -> 0 | R35: =SUM(D35:J35,P35) -> 0
A37: Balance at 31 December 2023 | D37: =SUM(D28,D2,D33,D35) -> 4531559733 | F37: =SUM(F28,F2,F33,F35) -> 909993447 | H37: =SUM(H28,H2,H33,H35) -> 295260000 | J37: =SUM(J28,J2,J33,J35) -> 522085326 | L37: =SUM(L28,L2,L33,L35) -> -150304 | N37: =SUM(N28,N2,N33,N35) -> 1285599818 | P37: =SUM(P28,P2,P33,P35) -> 1285449514 | R37: =SUM(R28,R2,R33,R35) -> 7544348020
A84: Retained earnings (deficit)

Sheet CF-12-13
A1: The Erawan Group Public Company Limited and its Subsidiaries
A2: Statement of cash flows
G4: Consolidated | J4: Separate
F5: financial statements | J5: financial statements
F6: Year ended 31 December | J6: Year ended 31 December
F7: 2023 | H7: 2022 | J7: 2023 | L7: 2022
F8: (in Baht)
A9: Cash flows from operating activities
A10: Profit (loss) for the year | F10: =PL!H33 -> 759876806 | H10: =PL!J33 -> -213062095 | J10: =PL!L33 -> 478579418 | L10: =PL!N33 -> -265686778
A11: Adjustments to reconcile profit (loss) to cash receipts (payments)
A12: Tax income | F12: -16525375 | H12: -25552830 | J12: -7760163 | L12: -5908377
A13: Finance costs | F13: 588988360 | H13: 457854856 | J13: 324168568 | L13: 261451193
A14: Depreciation and amortisation | F14: 901089744 | H14: 871843735 | J14: 413354520 | L14: 439247135
A15: Provisions for employee benefits | F15: 17460842 | H15: 15866800 | J15: -3654318 | L15: 6551671
A16: Share of profit of associates accounted for using equity method | F16: =-PL!H30 -> -36476679 | H16: -28599509 | J16: 0 | L16: 0
A17: (Reversal) loss on impairment of financial assets
B18: and non-financial assets | F18: -23481390 | H18: -4827690 | J18: -908141 | L18: 95718275
A19: Gain on disposal of property, plant and equipment | F19: -1220137 | H19: -21296457 | J19: -1048267 | L19: -22159945
A20: Loss on write-off non-refundable withholding tax deducted at source | F20: 300797 | H20: 140369 | J20: 0 | L20: 0
A21: Recognised rental deposits and deferred income to income | F21: -2024282 | H21: -681540 | J21: -2024096 | L21: -674699
A22: Dividend income | F22: 0 | H22: 0 | J22: -3152190 | L22: -16694685
A23: Interest income | F23: -6825646 | H23: -2681086 | J23: -46242003 | L23: -28808371
F24: =SUM(F9:F23) -> 2181163040 | H24: =SUM(H9:H23) -> 1049004553 | J24: =SUM(J9:J23) -> 1151313328 | L24: =SUM(L9:L23) -> 463035419
A25: Changes in operating assets and liabilities
A26: Trade accounts receivable | F26: 13267573 | H26: -48351948 | J26: 14038182 | L26: -20134166
A27: Inventories | F27: -5724403 | H27: -4197543 | J27: 1097837 | L27: -1727438
A28: Value added tax refundable | F28: -56246498 | H28: 11428998 | J28: 0 | L28: 0
A29: Other current assets | F29: 28167957 | H29: 20208438 | J29: -91741115 | L29: 11330069
A30: Deposits for lease of land, building and equipment | F30: -2585569 | H30: -3409438 | J30: 18162845 | L30: -1143143
A31: Other non-current assets | F31: 29611958 | H31: 13912302 | J31: -6341739 | L31: 627986
A32: Trade accounts payable | F32: -7769954 | H32: 91279742 | J32: 3043662 | L32: 25118243
A33: Employee benefits paid | F33: -10686542 | H33: -6927384 | J33: -4741526 | L33: -4888667
A34: Other current liabilities | F34: 104137053 | H34: 197089122 | J34: 18080835 | L34: 126497908
A35: Deposits from lessees | F35: 22006603 | H35: -13990228 | J35: -1326589 | L35: -1371763
A36: Net cash from operations | F36: =SUM(F24:F35) -> 2295341218 | H36: =SUM(H24:H35) -> 1306046614 | J36: =SUM(J24:J35) -> 1101585720 | L36: =SUM(L24:L35) -> 597344448
A37: Income taxes received (paid) | F37: -6256220 | H37: -16650296 | J37: 3375992 | L37: -8773597
A38: Net cash from operating activities | F38: =SUM(F36:F37) -> 2289084998 | H38: =SUM(H36:H37) -> 1289396318 | J38: =SUM(J36:J37) -> 1104961712 | L38: =SUM(L36:L37) -> 588570851
A40: The Erawan Group Public Company Limited and its Subsidiaries
A41: Statement of cash flows
G43: Consolidated | J43: Separate
...
